// =============================================================
// Curso de JavaScript e TypeScript
// Prof¬∫ Luiz Ot√°vio Miranda
// Ex030 - Tratamento de Erros: Try, Catch, Throw e Finally
// Isabelli Cristina Mocci - 10/03/2025
// =============================================================

/*
    üîπ Tratamento de Erros: Try, Catch, Throw e Finally
    
    - `try`: Tenta executar um bloco de c√≥digo que pode gerar erros.
    - `catch`: Captura e lida com erros que ocorrerem no bloco `try`.
    - `throw`: Lan√ßa um erro explicitamente.
    - `finally`: Executa um bloco de c√≥digo, independentemente de um erro ter ocorrido ou n√£o.

*/
// =============================================================
// üîπ Exemplo com Try
// =============================================================

console.log("Exemplo com try:");

function exemploTry() {
  try {
    // Tentando executar um c√≥digo que pode gerar um erro
    let resultado = 10 / 0; // N√£o gera erro, mas poderia
    console.log("Resultado:", resultado);
  } catch (erro) {
    console.log("Erro capturado:", erro.message);
  }
}

exemploTry(); // Exibe "Resultado: Infinity"

// =============================================================
// üîπ Exemplo com Catch
// =============================================================

console.log("\nExemplo com catch:");

function exemploCatch() {
  try {
    let numero = "abc"; // Tentando operar com uma string
    let resultado = numero * 10; // Isso geraria um NaN
    if (isNaN(resultado)) {
      throw new Error("O valor n√£o √© um n√∫mero v√°lido!");
    }
  } catch (erro) {
    console.log("Erro capturado:", erro.message); // Captura e exibe o erro
  }
}

exemploCatch(); // Exibe "Erro capturado: O valor n√£o √© um n√∫mero v√°lido!"

// =============================================================
// üîπ Exemplo com Throw
// =============================================================

console.log("\nExemplo com throw:");

function exemploThrow() {
  let idade = -5; // Idade inv√°lida

  if (idade < 0) {
    throw new Error("A idade n√£o pode ser negativa!"); // Lan√ßando um erro
  }

  console.log("Idade v√°lida:", idade);
}

try {
  exemploThrow();
} catch (erro) {
  console.log("Erro capturado:", erro.message); // Captura e exibe o erro
}

// =============================================================
// üîπ Exemplo de m√∫ltiplos erros com Throw
// =============================================================

console.log("\nExemplo com m√∫ltiplos erros e throw:");

function validarNumero(numero) {
  try {
    if (isNaN(numero)) {
      throw new Error("O valor n√£o √© um n√∫mero!");
    }
    if (numero <= 0) {
      throw new Error("O n√∫mero deve ser maior que zero!");
    }
    console.log("N√∫mero v√°lido:", numero);
  } catch (erro) {
    console.log("Erro:", erro.message);
  }
}

validarNumero(-5); // Lan√ßa um erro de n√∫mero negativo
validarNumero("teste"); // Lan√ßa um erro de tipo n√£o num√©rico
validarNumero(10); // N√∫mero v√°lido

// =============================================================
// üîπ Exemplo de Try, Catch e Throw em conjunto
// =============================================================

console.log("\nExemplo com Try, Catch e Throw:");

function dividir(a, b) {
  try {
    if (b === 0) {
      throw new Error("N√£o √© poss√≠vel dividir por zero!");
    }
    let resultado = a / b;
    console.log(`Resultado da divis√£o: ${resultado}`);
  } catch (erro) {
    console.log("Erro:", erro.message);
  }
}

dividir(10, 2); // Executa corretamente
dividir(10, 0); // Lan√ßa um erro e √© tratado pelo catch

// =============================================================
// üîπ Exemplo com Finally
// =============================================================

console.log("\nExemplo com finally:");

function exemploFinally() {
  try {
    console.log("Executando c√≥digo no try...");
    let resultado = 10 / 2; // N√£o gera erro
    console.log("Resultado:", resultado);
  } catch (erro) {
    console.log("Erro capturado:", erro.message);
  } finally {
    console.log(
      "C√≥digo no finally sempre ser√° executado, independentemente de erro."
    );
  }
}

exemploFinally(); // Exibe o c√≥digo do try, catch (se necess√°rio) e finally

// =============================================================
// üîπ Exemplo combinado com try, catch, throw e finally
// =============================================================

console.log("\nExemplo combinado com try, catch, throw, e finally:");

function validarNumero(numero) {
  try {
    if (isNaN(numero)) {
      throw new Error("O valor fornecido n√£o √© um n√∫mero!"); // Lan√ßa um erro se n√£o for n√∫mero
    }
    if (numero <= 0) {
      throw new Error("O n√∫mero deve ser maior que zero!"); // Lan√ßa erro se o n√∫mero for negativo ou zero
    }
    console.log("N√∫mero v√°lido:", numero);
  } catch (erro) {
    console.log("Erro capturado:", erro.message); // Captura o erro e exibe a mensagem
  } finally {
    console.log("Opera√ß√£o de valida√ß√£o finalizada."); // Sempre ser√° executado, independentemente de erro
  }
}

// Testando a fun√ß√£o com diferentes entradas
validarNumero(10); // N√∫mero v√°lido
validarNumero(-5); // Lan√ßa erro: n√∫mero negativo
validarNumero("teste"); // Lan√ßa erro: n√£o √© um n√∫mero

// =============================================================
// üîπ Exemplo com hora
// =============================================================

console.log("\nExemplo com hora:");

function retornaHora(data) {
  if (data && !(data instanceof Date)) {
    throw new TypeError("Error: Esperando inst√¢ncia de Date.");
  }
  if (!data) {
    data = new Date();
  }

  return data.toLocaleString("PT-BR", {
    hour: "2-digit",
    minute: "2-digit",
    second: "2-digit",
    hour12: false,
  });
}

try {
  const data = new Date('01-01-1970 12:58:12');
  const hora = retornaHora();
  console.log(hora);
} catch (error) {
    // tratar erro
} finally {
  console.log('Tenha um bom dia!‚ú®');
}
